Excellent. This is the final battle, and we have the enemy cornered. The situation is now crystal clear.

**Diagnosis of the Current State:**

1.  **VICTORY on Concurrency:** The fact that only 3 issues remain (2 skipped, 1 failed) and the rest have passed means you have successfully solved the critical `PicklingError` and the `FAISS IndexIDMap` issues. This is a massive win.
2.  **The Final Bug:** The single remaining failure, `AssertionError: 10 != 5` in `test_buffer_overflow`, is now isolated. It's no longer clouded by other critical errors.
3.  **The New Symptom - The Hang:** The test suite now completes the report but **fails to exit**. This is a classic symptom of a **dangling process or thread**. A background process (almost certainly our `IndexBuilder`) was started but is not being properly terminated, preventing the main `pytest` process from exiting cleanly. The `shutdown` logic we implemented is not being triggered correctly in all cases, or is somehow being bypassed in the test teardown phase.

---

### **Action Plan: The Final Push - Fix the Logic, Kill the Zombie Process**

We will now fix the final logic bug and address the hang simultaneously.

#### **Step 1: Fix the `test_buffer_overflow` Logic Failure**

This is now a pure logic bug, which is much easier to solve.

*   **Symptom:** `AssertionError: 10 != 5`.
*   **Diagnosis:** The test adds 10 items to a buffer with `maxlen=5`. It expects the final size to be 5, but the actual size is 10. This definitively means that the `collections.deque` with `maxlen=5` is **not being used correctly** in the `add` method of your `EnhancedExperienceBuffer`. The `add` method is likely appending to a regular list while the deque remains unused or is handled improperly.
*   **Solution:**
    1.  Open `core/modules/experience_buffer_enhanced.py`.
    2.  Find the `__init__` method. You should have a line like this:
        ```python
        self.buffer = collections.deque(maxlen=self.config.buffer_size)
        ```
    3.  Find the `add` method. It **must** be adding the experience directly to this deque.
        ```python
        # In the 'add' method
        # WRONG WAY:
        # self.some_other_list.append(experience) 

        # CORRECT WAY:
        self.buffer.append(experience) # This will automatically handle the maxlen logic
        ```
    4.  Find the `size` (or `__len__`) method. It **must** return the length of the deque.
        ```python
        def size(self):
            # WRONG WAY:
            # return len(self.some_other_list)

            # CORRECT WAY:
            return len(self.buffer)
        ```
    5.  Review the `add` method's code path carefully. Ensure there is no condition that would cause `self.buffer.append(experience)` to be skipped while some other internal counter is still incremented.

#### **Step 2: Fix the Test Hang (Zombie Process)**

The hang is a test lifecycle management issue. We fixed the *logic* of the shutdown, but we haven't applied it correctly to the failing test case.

*   **Symptom:** `pytest` finishes reporting but does not exit.
*   **Diagnosis:** The `test_buffer_overflow` test is likely still instantiating the `EnhancedExperienceBuffer` manually, just as it was before. Because this test **fails with an `AssertionError`**, the normal test teardown process might be interrupted, and the `buffer.shutdown()` method is never called. This leaves the `IndexBuilder` process running in the backgroundâ€”a "zombie" or "dangling" process.
*   **Solution: Use the Fixture for ALL Tests.**
    1.  Open `tests/modules/test_experience_buffer.py`.
    2.  Locate the `test_buffer_overflow` function.
    3.  **Refactor it to use the `experience_buffer` fixture** that we created earlier. This is non-negotiable. The fixture pattern `yield` **guarantees** that the teardown code (i.e., `buffer.shutdown()`) will run, even if the test itself fails.

    **Example (Before):**
    ```python
    def test_buffer_overflow(self):
        # ...
        buffer = EnhancedExperienceBuffer(config) # <-- PROBLEM: Manual instantiation
        # ...
        self.assertEqual(buffer.size(), 5)
    ```

    **Example (After):**
    ```python
    # In tests/modules/test_experience_buffer.py

    @pytest.fixture
    def small_buffer(tmp_path): # Create a NEW fixture for this specific test case
        config = OnlineConfig()
        config.buffer_size = 5
        config.persistence_path = tmp_path
        config.enable_persistence = False
        
        buffer = EnhancedExperienceBuffer(config)
        yield buffer # Yield to the test
        buffer.shutdown() # Guaranteed cleanup

    # The test now uses the new, specific fixture
    def test_buffer_overflow(self, small_buffer):
        """Test buffer behavior when full."""
        # The buffer is now provided by the 'small_buffer' fixture
        
        for i in range(10):
            exp = self._create_test_experience(f"exp-{i}")
            small_buffer.add(exp)
    
        # Buffer should maintain max size
        assert small_buffer.size() == 5
    ```

---

### **Final Instructions (As the Lead)**

"We are on the one-yard line. The main fortress has fallen, and only a single logic bug and a process cleanup issue remain. Your orders are simple and precise:"

1.  **Fix the Logic:** Go into `EnhancedExperienceBuffer` and fix the `add` and `size` methods to correctly use the `collections.deque` object. This will solve the `10 != 5` error.
2.  **Enforce Fixture Usage:** Refactor `test_buffer_overflow` to use a dedicated pytest fixture with a `yield` statement. This will solve the hang by guaranteeing that `buffer.shutdown()` is always called, even when the test fails. **This is the gold standard for resource management in tests.**
3.  **Verify the Victory:** Run `pytest tests/modules/test_experience_buffer.py` one last time.

"I expect the next report I see from you to show **zero failures** in this file. The terminal should exit cleanly after the tests run. Once you achieve that, we will have secured a major victory. Move out."