Of course. Here is a comprehensive, detailed, step-by-step action plan in English to resolve the one hanging test and the three failing tests from the latest report.

**“Excellent. We have pinpointed the final cluster of failures in the `InferenceEngine` module. These are advanced bugs related to concurrency, error handling, and sophisticated mocking. By fixing them, we are not just fixing tests; we are fortifying the core of our system. Let's proceed with precision.”**

---

### **Action Plan: Final Hardening of `InferenceEngine` Module**

This plan is divided into four distinct surgical strikes, one for each identified issue.

---

#### **Strike 1: Fix the Hanging Test (`test_run_main_loop_empty_queue_timeout`)**

*   **Objective**: Eradicate the infinite loop that causes the test to hang, by making the test controllable.
*   **Root Cause**: The test calls the `run()` method, which contains an unbounded `while self.is_running:` loop. The test mocks `queue.get()` to always raise `Empty`, creating a tight, infinite CPU loop that never exits.
*   **Solution**: We will refactor the test to validate the single-loop-iteration behavior directly, which is a more robust unit testing pattern, instead of trying to run the unbounded loop.

##### **Step-by-Step Implementation:**

1.  **Refactor `InferenceEngine` for Testability (Recommended Best Practice):**
    *   **File**: `core/engine/inference_engine.py`
    *   **Action**: Isolate the logic within the `run` method's `while` loop into a new, private method called `_main_loop_iteration`. This makes the core logic testable without running an infinite loop.

    ```python
    # In core/engine/inference_engine.py

    def _main_loop_iteration(self):
        """Performs a single, non-blocking iteration of the main event loop."""
        try:
            timeout = self.config.get('queue_timeout', 1.0)
            request = self.request_queue.get(timeout=timeout)

            if request is None:
                self.is_running = False # Signal to stop the loop
                return

            # ... all your request processing logic ...

        except queue.Empty:
            log.debug("No request in queue, continuing.")
            # This is not an error, just return to allow the next loop
            return
        except Exception as e:
            log.error(f"Critical error in main loop: {e}", exc_info=True)
            self.is_running = False # Stop on critical errors
    
    def run(self):
        """The main entry point to start the engine's event loop."""
        # ... setup threads ...
        self.is_running = True
        while self.is_running:
            self._main_loop_iteration()
        # ... shutdown logic ...
    ```

2.  **Rewrite the Test to be Deterministic:**
    *   **File**: `tests/engine/test_inference_engine.py`
    *   **Action**: Replace the old hanging test function with this new, robust version that calls the single-iteration method.

    ```python
    # In tests/engine/test_inference_engine.py -> in the appropriate test class

    def test_main_loop_iteration_handles_empty_queue_gracefully(self):
        """
        Verifies that a single iteration of the main loop handles a queue.Empty
        exception gracefully without crashing or raising an unhandled error.
        """
        from queue import Empty

        # 1. Mock the queue to always raise the Empty exception on get()
        self.engine.request_queue.get = MagicMock(side_effect=Empty)
        
        try:
            # 2. Call the single, non-looping iteration method
            self.engine._main_loop_iteration()
            # 3. If the code reaches here, it means the exception was caught
            #    and handled as expected. The test implicitly passes.
        except Exception as e:
            # 4. If any *other* exception was raised, the test must fail.
            pytest.fail(f"The main loop iteration failed unexpectedly with: {e}")
    ```

---

#### **Strike 2: Fix the `psutil` Mock (`test_monitoring_loop_memory_info_error`)**

*   **Objective**: Correct the `patch` target to successfully mock the `psutil` library.
*   **Root Cause**: The test tries to patch `'core.engine.inference_engine.psutil.Process'`, which is an invalid path. The `inference_engine` module imports `psutil`, so we must patch `psutil` within that module's namespace.
*   **Solution**:

##### **Step-by-Step Implementation:**

1.  **File**: `tests/engine/test_inference_engine.py`
2.  **Test Function**: `test_monitoring_loop_memory_info_error`
3.  **Action**: Correct the target string in the `patch` call.

    **Before (Incorrect):**
    ```python
    with patch('core.engine.inference_engine.psutil.Process') as mock_process_class:
        ...
    ```

    **After (Correct):**
    ```python
    # Target 'psutil' as it is imported and used in the 'inference_engine' module.
    with patch('core.engine.inference_engine.psutil') as mock_psutil:
        # Configure the mock to raise an error when Process().memory_info() is called.
        mock_process_instance = mock_psutil.Process.return_value
        mock_process_instance.memory_info.side_effect = Exception("Simulated psutil error")

        # Now, call the code that uses psutil
        with self.assertLogs(level='ERROR') as log:
            self.engine._monitoring_loop_iteration() # Assuming a similar refactor for testability
            self.assertIn("Failed to gather system stats", log.output[0])
    ```

---

#### **Strike 3: Fix the Error Handling Test (`test_process_cleanup_confirmations_unexpected_error`)**

*   **Objective**: Fix the test that verifies error logging.
*   **Root Cause**: The test asserts that `mock_logger.error` was called, but it wasn't. This implies the corresponding `try...except` block in the source code is either missing, too broad (e.g., `except: pass`), or is logging at a different level (e.g., `logger.warning`).
*   **Solution**:

##### **Step-by-Step Implementation:**

1.  **File**: `core/engine/inference_engine.py`
2.  **Method**: `_process_cleanup_confirmations`
3.  **Action**: Ensure a robust `try...except` block exists and correctly logs errors.

    ```python
    # In core/engine/inference_engine.py

    def _process_cleanup_confirmations(self):
        """Safely process all available cleanup confirmations from the worker."""
        while not self.cleanup_confirmation_queue.empty():
            try:
                shm_name = self.cleanup_confirmation_queue.get_nowait()
                if shm_name in self.shm_manager.pending_shm:
                    log.debug(f"[Watchdog] Received cleanup confirmation for: {shm_name}")
                    del self.shm_manager.pending_shm[shm_name]
            except queue.Empty:
                # This is normal, do nothing.
                break
            except Exception as e:
                # This block is what the test is looking for.
                # It MUST call logger.error.
                log.error(f"[Watchdog] Unexpected error processing cleanup queue: {e}", exc_info=True)
                continue # Continue to the next item
    ```
    With this code in place, the test `mock_logger.error.assert_called()` will now pass.

---

#### **Strike 4: Fix the `delitem` Mock (`test_shared_memory_unlink_error_handling`)**

*   **Objective**: Correct the `patch` target for mocking a dictionary deletion.
*   **Root Cause**: The test tries to patch `'builtins.delitem'`, which does not exist. The `del my_dict[key]` statement calls the `__delitem__` method of the `my_dict` object.
*   **Solution**:

##### **Step-by-Step Implementation:**

1.  **File**: `tests/engine/test_inference_engine.py`
2.  **Test Function**: `test_shared_memory_unlink_error_handling`
3.  **Action**: Use `patch.object` to target the `__delitem__` method of the specific dictionary instance.

    **Before (Incorrect):**
    ```python
    with patch('builtins.delitem', side_effect=Exception("Deletion failed")):
        ...
    ```

    **After (Correct):**
    ```python
    # Target the __delitem__ method of the actual dictionary object.
    cache_dict = self.engine.shm_manager._shared_memory_cache
    with patch.object(cache_dict, '__delitem__', 
                      side_effect=Exception("Simulated deletion failure")) as mock_delete:
        
        with self.assertLogs(level='ERROR') as log:
            # This call will internally try `del cache_dict[shm_name]`, triggering our mock.
            self.engine.shm_manager._unlink_segment("test_error_segment")
            
            # Verify that the error was caught and logged.
            self.assertIn("Failed to remove segment from cache", log.output[0])
    ```